/usr/local/lib/python3.7/site-packages/celery/platforms.py:801: RuntimeWarning: You're running the worker with superuser privileges: this is
absolutely not recommended!

Please specify a different user using the --uid option.

User information: uid=0 euid=0 gid=0 egid=0

  uid=uid, euid=euid, gid=gid, egid=egid,
[2019-11-03 12:27:42,117: ERROR/MainProcess] consumer: Cannot connect to amqp://celery:**@rabbitmq:5672/my_vhost: failed to resolve broker hostname.
Trying again in 2.00 seconds...

[2019-11-03 12:27:44,714: ERROR/MainProcess] consumer: Cannot connect to amqp://celery:**@rabbitmq:5672/my_vhost: failed to resolve broker hostname.
Trying again in 4.00 seconds...

[2019-11-03 12:27:48,851: ERROR/MainProcess] consumer: Cannot connect to amqp://celery:**@rabbitmq:5672/my_vhost: failed to resolve broker hostname.
Trying again in 6.00 seconds...


worker: Warm shutdown (MainProcess)
/usr/local/lib/python3.7/site-packages/celery/platforms.py:801: RuntimeWarning: You're running the worker with superuser privileges: this is
absolutely not recommended!

Please specify a different user using the --uid option.

User information: uid=0 euid=0 gid=0 egid=0

  uid=uid, euid=euid, gid=gid, egid=egid,
[2019-11-03 12:33:29,883: ERROR/MainProcess] consumer: Cannot connect to amqp://celery:**@rabbitmq:5672/my_vhost: [Errno 111] Connection refused.
Trying again in 2.00 seconds...

[2019-11-03 12:33:31,925: ERROR/MainProcess] consumer: Cannot connect to amqp://celery:**@rabbitmq:5672/my_vhost: [Errno 111] Connection refused.
Trying again in 4.00 seconds...

[2019-11-03 12:33:35,951: ERROR/MainProcess] consumer: Cannot connect to amqp://celery:**@rabbitmq:5672/my_vhost: [Errno 111] Connection refused.
Trying again in 6.00 seconds...

[2019-11-03 12:33:41,948: ERROR/MainProcess] consumer: Cannot connect to amqp://celery:**@rabbitmq:5672/my_vhost: [Errno 111] Connection refused.
Trying again in 8.00 seconds...

[2019-11-03 12:33:49,987: ERROR/MainProcess] consumer: Cannot connect to amqp://celery:**@rabbitmq:5672/my_vhost: [Errno 111] Connection refused.
Trying again in 10.00 seconds...

[2019-11-03 12:34:01,205: WARNING/MainProcess] /usr/local/lib/python3.7/site-packages/celery/fixups/django.py:202: UserWarning: Using settings.DEBUG leads to a memory leak, never use this setting in production environments!
  warnings.warn('Using settings.DEBUG leads to a memory leak, never '

worker: Warm shutdown (MainProcess)
/usr/local/lib/python3.7/site-packages/celery/platforms.py:801: RuntimeWarning: You're running the worker with superuser privileges: this is
absolutely not recommended!

Please specify a different user using the --uid option.

User information: uid=0 euid=0 gid=0 egid=0

  uid=uid, euid=euid, gid=gid, egid=egid,
[2019-11-03 12:42:06,860: ERROR/MainProcess] consumer: Cannot connect to amqp://celery:**@rabbitmq:15672/my_vhost: timed out.
Trying again in 2.00 seconds...

[2019-11-03 12:42:12,860: ERROR/MainProcess] consumer: Cannot connect to amqp://celery:**@rabbitmq:15672/my_vhost: timed out.
Trying again in 4.00 seconds...

[2019-11-03 12:42:20,881: ERROR/MainProcess] consumer: Cannot connect to amqp://celery:**@rabbitmq:15672/my_vhost: timed out.
Trying again in 6.00 seconds...

[2019-11-03 12:42:31,043: ERROR/MainProcess] consumer: Cannot connect to amqp://celery:**@rabbitmq:15672/my_vhost: timed out.
Trying again in 8.00 seconds...

[2019-11-03 12:42:43,038: ERROR/MainProcess] consumer: Cannot connect to amqp://celery:**@rabbitmq:15672/my_vhost: timed out.
Trying again in 10.00 seconds...


worker: Warm shutdown (MainProcess)
/usr/local/lib/python3.7/site-packages/celery/platforms.py:801: RuntimeWarning: You're running the worker with superuser privileges: this is
absolutely not recommended!

Please specify a different user using the --uid option.

User information: uid=0 euid=0 gid=0 egid=0

  uid=uid, euid=euid, gid=gid, egid=egid,
[2019-11-03 12:42:56,101: WARNING/MainProcess] /usr/local/lib/python3.7/site-packages/celery/fixups/django.py:202: UserWarning: Using settings.DEBUG leads to a memory leak, never use this setting in production environments!
  warnings.warn('Using settings.DEBUG leads to a memory leak, never '

worker: Warm shutdown (MainProcess)
/usr/local/lib/python3.7/site-packages/celery/platforms.py:801: RuntimeWarning: You're running the worker with superuser privileges: this is
absolutely not recommended!

Please specify a different user using the --uid option.

User information: uid=0 euid=0 gid=0 egid=0

  uid=uid, euid=euid, gid=gid, egid=egid,
[2019-11-03 17:05:34,489: ERROR/MainProcess] consumer: Cannot connect to amqp://celery:**@rabbitmq:5672/my_vhost: [Errno 111] Connection refused.
Trying again in 2.00 seconds...

[2019-11-03 17:05:36,570: ERROR/MainProcess] consumer: Cannot connect to amqp://celery:**@rabbitmq:5672/my_vhost: [Errno 111] Connection refused.
Trying again in 4.00 seconds...

[2019-11-03 17:05:40,605: ERROR/MainProcess] consumer: Cannot connect to amqp://celery:**@rabbitmq:5672/my_vhost: [Errno 111] Connection refused.
Trying again in 6.00 seconds...

[2019-11-03 17:05:46,731: ERROR/MainProcess] consumer: Cannot connect to amqp://celery:**@rabbitmq:5672/my_vhost: [Errno 111] Connection refused.
Trying again in 8.00 seconds...

[2019-11-03 17:05:54,815: ERROR/MainProcess] consumer: Cannot connect to amqp://celery:**@rabbitmq:5672/my_vhost: [Errno 111] Connection refused.
Trying again in 10.00 seconds...

[2019-11-03 17:06:04,847: ERROR/MainProcess] consumer: Cannot connect to amqp://celery:**@rabbitmq:5672/my_vhost: [Errno 111] Connection refused.
Trying again in 12.00 seconds...

[2019-11-03 17:06:18,019: WARNING/MainProcess] /usr/local/lib/python3.7/site-packages/celery/fixups/django.py:202: UserWarning: Using settings.DEBUG leads to a memory leak, never use this setting in production environments!
  warnings.warn('Using settings.DEBUG leads to a memory leak, never '
/usr/local/lib/python3.7/site-packages/celery/platforms.py:801: RuntimeWarning: You're running the worker with superuser privileges: this is
absolutely not recommended!

Please specify a different user using the --uid option.

User information: uid=0 euid=0 gid=0 egid=0

  uid=uid, euid=euid, gid=gid, egid=egid,
[2019-11-03 17:53:42,561: ERROR/MainProcess] consumer: Cannot connect to amqp://celery:**@rabbitmq:5672/my_vhost: [Errno 111] Connection refused.
Trying again in 2.00 seconds...

[2019-11-03 17:53:44,628: ERROR/MainProcess] consumer: Cannot connect to amqp://celery:**@rabbitmq:5672/my_vhost: [Errno 111] Connection refused.
Trying again in 4.00 seconds...

[2019-11-03 17:53:48,676: ERROR/MainProcess] consumer: Cannot connect to amqp://celery:**@rabbitmq:5672/my_vhost: [Errno 111] Connection refused.
Trying again in 6.00 seconds...

[2019-11-03 17:53:54,705: ERROR/MainProcess] consumer: Cannot connect to amqp://celery:**@rabbitmq:5672/my_vhost: [Errno 111] Connection refused.
Trying again in 8.00 seconds...

[2019-11-03 17:54:02,731: ERROR/MainProcess] consumer: Cannot connect to amqp://celery:**@rabbitmq:5672/my_vhost: [Errno 111] Connection refused.
Trying again in 10.00 seconds...

[2019-11-03 17:54:13,916: WARNING/MainProcess] /usr/local/lib/python3.7/site-packages/celery/fixups/django.py:202: UserWarning: Using settings.DEBUG leads to a memory leak, never use this setting in production environments!
  warnings.warn('Using settings.DEBUG leads to a memory leak, never '
[2019-11-03 17:55:08,635: ERROR/Beat] Process Beat
Traceback (most recent call last):
  File "/usr/local/lib/python3.7/site-packages/kombu/utils/objects.py", line 42, in __get__
    return obj.__dict__[self.__name__]
KeyError: 'scheduler'

During handling of the above exception, another exception occurred:

Traceback (most recent call last):
  File "/usr/local/lib/python3.7/site-packages/django/db/backends/base/base.py", line 217, in ensure_connection
    self.connect()
  File "/usr/local/lib/python3.7/site-packages/django/db/backends/base/base.py", line 195, in connect
    self.connection = self.get_new_connection(conn_params)
  File "/usr/local/lib/python3.7/site-packages/django/db/backends/postgresql/base.py", line 178, in get_new_connection
    connection = Database.connect(**conn_params)
  File "/usr/local/lib/python3.7/site-packages/psycopg2/__init__.py", line 126, in connect
    conn = _connect(dsn, connection_factory=connection_factory, **kwasync)
psycopg2.OperationalError: could not connect to server: Connection refused
	Is the server running on host "172.19.0.2" and accepting
	TCP/IP connections on port 5432?


The above exception was the direct cause of the following exception:

Traceback (most recent call last):
  File "/usr/local/lib/python3.7/site-packages/billiard/process.py", line 327, in _bootstrap
    self.run()
  File "/usr/local/lib/python3.7/site-packages/celery/beat.py", line 673, in run
    self.service.start(embedded_process=True)
  File "/usr/local/lib/python3.7/site-packages/celery/beat.py", line 588, in start
    humanize_seconds(self.scheduler.max_interval))
  File "/usr/local/lib/python3.7/site-packages/kombu/utils/objects.py", line 44, in __get__
    value = obj.__dict__[self.__name__] = self.__get(obj)
  File "/usr/local/lib/python3.7/site-packages/celery/beat.py", line 632, in scheduler
    return self.get_scheduler()
  File "/usr/local/lib/python3.7/site-packages/celery/beat.py", line 627, in get_scheduler
    lazy=lazy,
  File "/usr/local/lib/python3.7/site-packages/django_celery_beat/schedulers.py", line 229, in __init__
    Scheduler.__init__(self, *args, **kwargs)
  File "/usr/local/lib/python3.7/site-packages/celery/beat.py", line 226, in __init__
    self.setup_schedule()
  File "/usr/local/lib/python3.7/site-packages/django_celery_beat/schedulers.py", line 237, in setup_schedule
    self.install_default_entries(self.schedule)
  File "/usr/local/lib/python3.7/site-packages/django_celery_beat/schedulers.py", line 358, in schedule
    self._schedule = self.all_as_schedule()
  File "/usr/local/lib/python3.7/site-packages/django_celery_beat/schedulers.py", line 243, in all_as_schedule
    for model in self.Model.objects.enabled():
  File "/usr/local/lib/python3.7/site-packages/django/db/models/query.py", line 274, in __iter__
    self._fetch_all()
  File "/usr/local/lib/python3.7/site-packages/django/db/models/query.py", line 1242, in _fetch_all
    self._result_cache = list(self._iterable_class(self))
  File "/usr/local/lib/python3.7/site-packages/django/db/models/query.py", line 55, in __iter__
    results = compiler.execute_sql(chunked_fetch=self.chunked_fetch, chunk_size=self.chunk_size)
  File "/usr/local/lib/python3.7/site-packages/django/db/models/sql/compiler.py", line 1098, in execute_sql
    cursor = self.connection.cursor()
  File "/usr/local/lib/python3.7/site-packages/django/db/backends/base/base.py", line 256, in cursor
    return self._cursor()
  File "/usr/local/lib/python3.7/site-packages/django/db/backends/base/base.py", line 233, in _cursor
    self.ensure_connection()
  File "/usr/local/lib/python3.7/site-packages/django/db/backends/base/base.py", line 217, in ensure_connection
    self.connect()
  File "/usr/local/lib/python3.7/site-packages/django/db/utils.py", line 89, in __exit__
    raise dj_exc_value.with_traceback(traceback) from exc_value
  File "/usr/local/lib/python3.7/site-packages/django/db/backends/base/base.py", line 217, in ensure_connection
    self.connect()
  File "/usr/local/lib/python3.7/site-packages/django/db/backends/base/base.py", line 195, in connect
    self.connection = self.get_new_connection(conn_params)
  File "/usr/local/lib/python3.7/site-packages/django/db/backends/postgresql/base.py", line 178, in get_new_connection
    connection = Database.connect(**conn_params)
  File "/usr/local/lib/python3.7/site-packages/psycopg2/__init__.py", line 126, in connect
    conn = _connect(dsn, connection_factory=connection_factory, **kwasync)
django.db.utils.OperationalError: could not connect to server: Connection refused
	Is the server running on host "172.19.0.2" and accepting
	TCP/IP connections on port 5432?

[2019-11-03 17:55:08,650: WARNING/Beat] Process Beat:
[2019-11-03 17:55:08,652: WARNING/Beat] Traceback (most recent call last):
[2019-11-03 17:55:08,652: WARNING/Beat] File "/usr/local/lib/python3.7/site-packages/kombu/utils/objects.py", line 42, in __get__
    return obj.__dict__[self.__name__]
[2019-11-03 17:55:08,652: WARNING/Beat] KeyError: 'scheduler'
[2019-11-03 17:55:08,653: WARNING/Beat] During handling of the above exception, another exception occurred:
[2019-11-03 17:55:08,653: WARNING/Beat] Traceback (most recent call last):
[2019-11-03 17:55:08,653: WARNING/Beat] File "/usr/local/lib/python3.7/site-packages/django/db/backends/base/base.py", line 217, in ensure_connection
    self.connect()
[2019-11-03 17:55:08,654: WARNING/Beat] File "/usr/local/lib/python3.7/site-packages/django/db/backends/base/base.py", line 195, in connect
    self.connection = self.get_new_connection(conn_params)
[2019-11-03 17:55:08,654: WARNING/Beat] File "/usr/local/lib/python3.7/site-packages/django/db/backends/postgresql/base.py", line 178, in get_new_connection
    connection = Database.connect(**conn_params)
[2019-11-03 17:55:08,655: WARNING/Beat] File "/usr/local/lib/python3.7/site-packages/psycopg2/__init__.py", line 126, in connect
    conn = _connect(dsn, connection_factory=connection_factory, **kwasync)
[2019-11-03 17:55:08,655: WARNING/Beat] psycopg2.OperationalError: could not connect to server: Connection refused
	Is the server running on host "172.19.0.2" and accepting
	TCP/IP connections on port 5432?
[2019-11-03 17:55:08,655: WARNING/Beat] The above exception was the direct cause of the following exception:
[2019-11-03 17:55:08,656: WARNING/Beat] Traceback (most recent call last):
[2019-11-03 17:55:08,656: WARNING/Beat] File "/usr/local/lib/python3.7/site-packages/billiard/process.py", line 327, in _bootstrap
    self.run()
[2019-11-03 17:55:08,657: WARNING/Beat] File "/usr/local/lib/python3.7/site-packages/celery/beat.py", line 673, in run
    self.service.start(embedded_process=True)
[2019-11-03 17:55:08,657: WARNING/Beat] File "/usr/local/lib/python3.7/site-packages/celery/beat.py", line 588, in start
    humanize_seconds(self.scheduler.max_interval))
[2019-11-03 17:55:08,658: WARNING/Beat] File "/usr/local/lib/python3.7/site-packages/kombu/utils/objects.py", line 44, in __get__
    value = obj.__dict__[self.__name__] = self.__get(obj)
[2019-11-03 17:55:08,658: WARNING/Beat] File "/usr/local/lib/python3.7/site-packages/celery/beat.py", line 632, in scheduler
    return self.get_scheduler()
[2019-11-03 17:55:08,659: WARNING/Beat] File "/usr/local/lib/python3.7/site-packages/celery/beat.py", line 627, in get_scheduler
    lazy=lazy,
[2019-11-03 17:55:08,659: WARNING/Beat] File "/usr/local/lib/python3.7/site-packages/django_celery_beat/schedulers.py", line 229, in __init__
    Scheduler.__init__(self, *args, **kwargs)
[2019-11-03 17:55:08,659: WARNING/Beat] File "/usr/local/lib/python3.7/site-packages/celery/beat.py", line 226, in __init__
    self.setup_schedule()
[2019-11-03 17:55:08,659: WARNING/Beat] File "/usr/local/lib/python3.7/site-packages/django_celery_beat/schedulers.py", line 237, in setup_schedule
    self.install_default_entries(self.schedule)
[2019-11-03 17:55:08,660: WARNING/Beat] File "/usr/local/lib/python3.7/site-packages/django_celery_beat/schedulers.py", line 358, in schedule
    self._schedule = self.all_as_schedule()
[2019-11-03 17:55:08,660: WARNING/Beat] File "/usr/local/lib/python3.7/site-packages/django_celery_beat/schedulers.py", line 243, in all_as_schedule
    for model in self.Model.objects.enabled():
[2019-11-03 17:55:08,660: WARNING/Beat] File "/usr/local/lib/python3.7/site-packages/django/db/models/query.py", line 274, in __iter__
    self._fetch_all()
[2019-11-03 17:55:08,661: WARNING/Beat] File "/usr/local/lib/python3.7/site-packages/django/db/models/query.py", line 1242, in _fetch_all
    self._result_cache = list(self._iterable_class(self))
[2019-11-03 17:55:08,661: WARNING/Beat] File "/usr/local/lib/python3.7/site-packages/django/db/models/query.py", line 55, in __iter__
    results = compiler.execute_sql(chunked_fetch=self.chunked_fetch, chunk_size=self.chunk_size)
[2019-11-03 17:55:08,661: WARNING/Beat] File "/usr/local/lib/python3.7/site-packages/django/db/models/sql/compiler.py", line 1098, in execute_sql
    cursor = self.connection.cursor()
[2019-11-03 17:55:08,662: WARNING/Beat] File "/usr/local/lib/python3.7/site-packages/django/db/backends/base/base.py", line 256, in cursor
    return self._cursor()
[2019-11-03 17:55:08,662: WARNING/Beat] File "/usr/local/lib/python3.7/site-packages/django/db/backends/base/base.py", line 233, in _cursor
    self.ensure_connection()
[2019-11-03 17:55:08,663: WARNING/Beat] File "/usr/local/lib/python3.7/site-packages/django/db/backends/base/base.py", line 217, in ensure_connection
    self.connect()
[2019-11-03 17:55:08,663: WARNING/Beat] File "/usr/local/lib/python3.7/site-packages/django/db/utils.py", line 89, in __exit__
    raise dj_exc_value.with_traceback(traceback) from exc_value
[2019-11-03 17:55:08,663: WARNING/Beat] File "/usr/local/lib/python3.7/site-packages/django/db/backends/base/base.py", line 217, in ensure_connection
    self.connect()
[2019-11-03 17:55:08,664: WARNING/Beat] File "/usr/local/lib/python3.7/site-packages/django/db/backends/base/base.py", line 195, in connect
    self.connection = self.get_new_connection(conn_params)
[2019-11-03 17:55:08,664: WARNING/Beat] File "/usr/local/lib/python3.7/site-packages/django/db/backends/postgresql/base.py", line 178, in get_new_connection
    connection = Database.connect(**conn_params)
[2019-11-03 17:55:08,665: WARNING/Beat] File "/usr/local/lib/python3.7/site-packages/psycopg2/__init__.py", line 126, in connect
    conn = _connect(dsn, connection_factory=connection_factory, **kwasync)
[2019-11-03 17:55:08,665: WARNING/Beat] django.db.utils.OperationalError: could not connect to server: Connection refused
	Is the server running on host "172.19.0.2" and accepting
	TCP/IP connections on port 5432?

worker: Warm shutdown (MainProcess)
/usr/local/lib/python3.7/site-packages/celery/platforms.py:801: RuntimeWarning: You're running the worker with superuser privileges: this is
absolutely not recommended!

Please specify a different user using the --uid option.

User information: uid=0 euid=0 gid=0 egid=0

  uid=uid, euid=euid, gid=gid, egid=egid,
[2019-11-03 17:59:16,404: ERROR/MainProcess] consumer: Cannot connect to amqp://celery:**@rabbitmq:5672/my_vhost: [Errno 111] Connection refused.
Trying again in 2.00 seconds...

[2019-11-03 17:59:18,427: ERROR/MainProcess] consumer: Cannot connect to amqp://celery:**@rabbitmq:5672/my_vhost: [Errno 111] Connection refused.
Trying again in 4.00 seconds...

[2019-11-03 17:59:22,480: ERROR/MainProcess] consumer: Cannot connect to amqp://celery:**@rabbitmq:5672/my_vhost: [Errno 111] Connection refused.
Trying again in 6.00 seconds...

[2019-11-03 17:59:22,982: ERROR/Beat] Process Beat
Traceback (most recent call last):
  File "/usr/local/lib/python3.7/site-packages/kombu/utils/objects.py", line 42, in __get__
    return obj.__dict__[self.__name__]
KeyError: 'scheduler'

During handling of the above exception, another exception occurred:

Traceback (most recent call last):
  File "/usr/local/lib/python3.7/site-packages/django/db/backends/base/base.py", line 217, in ensure_connection
    self.connect()
  File "/usr/local/lib/python3.7/site-packages/django/db/backends/base/base.py", line 195, in connect
    self.connection = self.get_new_connection(conn_params)
  File "/usr/local/lib/python3.7/site-packages/django/db/backends/postgresql/base.py", line 178, in get_new_connection
    connection = Database.connect(**conn_params)
  File "/usr/local/lib/python3.7/site-packages/psycopg2/__init__.py", line 126, in connect
    conn = _connect(dsn, connection_factory=connection_factory, **kwasync)
psycopg2.OperationalError: could not connect to server: Connection refused
	Is the server running on host "172.19.0.2" and accepting
	TCP/IP connections on port 5432?


The above exception was the direct cause of the following exception:

Traceback (most recent call last):
  File "/usr/local/lib/python3.7/site-packages/billiard/process.py", line 327, in _bootstrap
    self.run()
  File "/usr/local/lib/python3.7/site-packages/celery/beat.py", line 673, in run
    self.service.start(embedded_process=True)
  File "/usr/local/lib/python3.7/site-packages/celery/beat.py", line 588, in start
    humanize_seconds(self.scheduler.max_interval))
  File "/usr/local/lib/python3.7/site-packages/kombu/utils/objects.py", line 44, in __get__
    value = obj.__dict__[self.__name__] = self.__get(obj)
  File "/usr/local/lib/python3.7/site-packages/celery/beat.py", line 632, in scheduler
    return self.get_scheduler()
  File "/usr/local/lib/python3.7/site-packages/celery/beat.py", line 627, in get_scheduler
    lazy=lazy,
  File "/usr/local/lib/python3.7/site-packages/django_celery_beat/schedulers.py", line 229, in __init__
    Scheduler.__init__(self, *args, **kwargs)
  File "/usr/local/lib/python3.7/site-packages/celery/beat.py", line 226, in __init__
    self.setup_schedule()
  File "/usr/local/lib/python3.7/site-packages/django_celery_beat/schedulers.py", line 237, in setup_schedule
    self.install_default_entries(self.schedule)
  File "/usr/local/lib/python3.7/site-packages/django_celery_beat/schedulers.py", line 358, in schedule
    self._schedule = self.all_as_schedule()
  File "/usr/local/lib/python3.7/site-packages/django_celery_beat/schedulers.py", line 243, in all_as_schedule
    for model in self.Model.objects.enabled():
  File "/usr/local/lib/python3.7/site-packages/django/db/models/query.py", line 274, in __iter__
    self._fetch_all()
  File "/usr/local/lib/python3.7/site-packages/django/db/models/query.py", line 1242, in _fetch_all
    self._result_cache = list(self._iterable_class(self))
  File "/usr/local/lib/python3.7/site-packages/django/db/models/query.py", line 55, in __iter__
    results = compiler.execute_sql(chunked_fetch=self.chunked_fetch, chunk_size=self.chunk_size)
  File "/usr/local/lib/python3.7/site-packages/django/db/models/sql/compiler.py", line 1098, in execute_sql
    cursor = self.connection.cursor()
  File "/usr/local/lib/python3.7/site-packages/django/db/backends/base/base.py", line 256, in cursor
    return self._cursor()
  File "/usr/local/lib/python3.7/site-packages/django/db/backends/base/base.py", line 233, in _cursor
    self.ensure_connection()
  File "/usr/local/lib/python3.7/site-packages/django/db/backends/base/base.py", line 217, in ensure_connection
    self.connect()
  File "/usr/local/lib/python3.7/site-packages/django/db/utils.py", line 89, in __exit__
    raise dj_exc_value.with_traceback(traceback) from exc_value
  File "/usr/local/lib/python3.7/site-packages/django/db/backends/base/base.py", line 217, in ensure_connection
    self.connect()
  File "/usr/local/lib/python3.7/site-packages/django/db/backends/base/base.py", line 195, in connect
    self.connection = self.get_new_connection(conn_params)
  File "/usr/local/lib/python3.7/site-packages/django/db/backends/postgresql/base.py", line 178, in get_new_connection
    connection = Database.connect(**conn_params)
  File "/usr/local/lib/python3.7/site-packages/psycopg2/__init__.py", line 126, in connect
    conn = _connect(dsn, connection_factory=connection_factory, **kwasync)
django.db.utils.OperationalError: could not connect to server: Connection refused
	Is the server running on host "172.19.0.2" and accepting
	TCP/IP connections on port 5432?

[2019-11-03 17:59:22,998: WARNING/Beat] Process Beat:
[2019-11-03 17:59:22,999: WARNING/Beat] Traceback (most recent call last):
[2019-11-03 17:59:23,002: WARNING/Beat] File "/usr/local/lib/python3.7/site-packages/kombu/utils/objects.py", line 42, in __get__
    return obj.__dict__[self.__name__]
[2019-11-03 17:59:23,002: WARNING/Beat] KeyError: 'scheduler'
[2019-11-03 17:59:23,003: WARNING/Beat] During handling of the above exception, another exception occurred:
[2019-11-03 17:59:23,003: WARNING/Beat] Traceback (most recent call last):
[2019-11-03 17:59:23,004: WARNING/Beat] File "/usr/local/lib/python3.7/site-packages/django/db/backends/base/base.py", line 217, in ensure_connection
    self.connect()
[2019-11-03 17:59:23,005: WARNING/Beat] File "/usr/local/lib/python3.7/site-packages/django/db/backends/base/base.py", line 195, in connect
    self.connection = self.get_new_connection(conn_params)
[2019-11-03 17:59:23,005: WARNING/Beat] File "/usr/local/lib/python3.7/site-packages/django/db/backends/postgresql/base.py", line 178, in get_new_connection
    connection = Database.connect(**conn_params)
[2019-11-03 17:59:23,006: WARNING/Beat] File "/usr/local/lib/python3.7/site-packages/psycopg2/__init__.py", line 126, in connect
    conn = _connect(dsn, connection_factory=connection_factory, **kwasync)
[2019-11-03 17:59:23,008: WARNING/Beat] psycopg2.OperationalError: could not connect to server: Connection refused
	Is the server running on host "172.19.0.2" and accepting
	TCP/IP connections on port 5432?
[2019-11-03 17:59:23,012: WARNING/Beat] The above exception was the direct cause of the following exception:
[2019-11-03 17:59:23,013: WARNING/Beat] Traceback (most recent call last):
[2019-11-03 17:59:23,014: WARNING/Beat] File "/usr/local/lib/python3.7/site-packages/billiard/process.py", line 327, in _bootstrap
    self.run()
[2019-11-03 17:59:23,016: WARNING/Beat] File "/usr/local/lib/python3.7/site-packages/celery/beat.py", line 673, in run
    self.service.start(embedded_process=True)
[2019-11-03 17:59:23,016: WARNING/Beat] File "/usr/local/lib/python3.7/site-packages/celery/beat.py", line 588, in start
    humanize_seconds(self.scheduler.max_interval))
[2019-11-03 17:59:23,017: WARNING/Beat] File "/usr/local/lib/python3.7/site-packages/kombu/utils/objects.py", line 44, in __get__
    value = obj.__dict__[self.__name__] = self.__get(obj)
[2019-11-03 17:59:23,018: WARNING/Beat] File "/usr/local/lib/python3.7/site-packages/celery/beat.py", line 632, in scheduler
    return self.get_scheduler()
[2019-11-03 17:59:23,018: WARNING/Beat] File "/usr/local/lib/python3.7/site-packages/celery/beat.py", line 627, in get_scheduler
    lazy=lazy,
[2019-11-03 17:59:23,019: WARNING/Beat] File "/usr/local/lib/python3.7/site-packages/django_celery_beat/schedulers.py", line 229, in __init__
    Scheduler.__init__(self, *args, **kwargs)
[2019-11-03 17:59:23,019: WARNING/Beat] File "/usr/local/lib/python3.7/site-packages/celery/beat.py", line 226, in __init__
    self.setup_schedule()
[2019-11-03 17:59:23,020: WARNING/Beat] File "/usr/local/lib/python3.7/site-packages/django_celery_beat/schedulers.py", line 237, in setup_schedule
    self.install_default_entries(self.schedule)
[2019-11-03 17:59:23,020: WARNING/Beat] File "/usr/local/lib/python3.7/site-packages/django_celery_beat/schedulers.py", line 358, in schedule
    self._schedule = self.all_as_schedule()
[2019-11-03 17:59:23,021: WARNING/Beat] File "/usr/local/lib/python3.7/site-packages/django_celery_beat/schedulers.py", line 243, in all_as_schedule
    for model in self.Model.objects.enabled():
[2019-11-03 17:59:23,021: WARNING/Beat] File "/usr/local/lib/python3.7/site-packages/django/db/models/query.py", line 274, in __iter__
    self._fetch_all()
[2019-11-03 17:59:23,022: WARNING/Beat] File "/usr/local/lib/python3.7/site-packages/django/db/models/query.py", line 1242, in _fetch_all
    self._result_cache = list(self._iterable_class(self))
[2019-11-03 17:59:23,024: WARNING/Beat] File "/usr/local/lib/python3.7/site-packages/django/db/models/query.py", line 55, in __iter__
    results = compiler.execute_sql(chunked_fetch=self.chunked_fetch, chunk_size=self.chunk_size)
[2019-11-03 17:59:23,024: WARNING/Beat] File "/usr/local/lib/python3.7/site-packages/django/db/models/sql/compiler.py", line 1098, in execute_sql
    cursor = self.connection.cursor()
[2019-11-03 17:59:23,025: WARNING/Beat] File "/usr/local/lib/python3.7/site-packages/django/db/backends/base/base.py", line 256, in cursor
    return self._cursor()
[2019-11-03 17:59:23,025: WARNING/Beat] File "/usr/local/lib/python3.7/site-packages/django/db/backends/base/base.py", line 233, in _cursor
    self.ensure_connection()
[2019-11-03 17:59:23,034: WARNING/Beat] File "/usr/local/lib/python3.7/site-packages/django/db/backends/base/base.py", line 217, in ensure_connection
    self.connect()
[2019-11-03 17:59:23,035: WARNING/Beat] File "/usr/local/lib/python3.7/site-packages/django/db/utils.py", line 89, in __exit__
    raise dj_exc_value.with_traceback(traceback) from exc_value
[2019-11-03 17:59:23,036: WARNING/Beat] File "/usr/local/lib/python3.7/site-packages/django/db/backends/base/base.py", line 217, in ensure_connection
    self.connect()
[2019-11-03 17:59:23,036: WARNING/Beat] File "/usr/local/lib/python3.7/site-packages/django/db/backends/base/base.py", line 195, in connect
    self.connection = self.get_new_connection(conn_params)
[2019-11-03 17:59:23,037: WARNING/Beat] File "/usr/local/lib/python3.7/site-packages/django/db/backends/postgresql/base.py", line 178, in get_new_connection
    connection = Database.connect(**conn_params)
[2019-11-03 17:59:23,037: WARNING/Beat] File "/usr/local/lib/python3.7/site-packages/psycopg2/__init__.py", line 126, in connect
    conn = _connect(dsn, connection_factory=connection_factory, **kwasync)
[2019-11-03 17:59:23,039: WARNING/Beat] django.db.utils.OperationalError: could not connect to server: Connection refused
	Is the server running on host "172.19.0.2" and accepting
	TCP/IP connections on port 5432?
[2019-11-03 17:59:28,535: ERROR/MainProcess] consumer: Cannot connect to amqp://celery:**@rabbitmq:5672/my_vhost: [Errno 111] Connection refused.
Trying again in 8.00 seconds...

[2019-11-03 17:59:36,674: ERROR/MainProcess] consumer: Cannot connect to amqp://celery:**@rabbitmq:5672/my_vhost: [Errno 111] Connection refused.
Trying again in 10.00 seconds...

[2019-11-03 17:59:47,773: WARNING/MainProcess] /usr/local/lib/python3.7/site-packages/celery/fixups/django.py:202: UserWarning: Using settings.DEBUG leads to a memory leak, never use this setting in production environments!
  warnings.warn('Using settings.DEBUG leads to a memory leak, never '

worker: Warm shutdown (MainProcess)
/usr/local/lib/python3.7/site-packages/celery/platforms.py:801: RuntimeWarning: You're running the worker with superuser privileges: this is
absolutely not recommended!

Please specify a different user using the --uid option.

User information: uid=0 euid=0 gid=0 egid=0

  uid=uid, euid=euid, gid=gid, egid=egid,
[2019-11-03 21:33:33,597: ERROR/MainProcess] consumer: Cannot connect to amqp://celery:**@rabbitmq:5672/my_vhost: [Errno 111] Connection refused.
Trying again in 2.00 seconds...

[2019-11-03 21:33:35,674: ERROR/MainProcess] consumer: Cannot connect to amqp://celery:**@rabbitmq:5672/my_vhost: [Errno 111] Connection refused.
Trying again in 4.00 seconds...

[2019-11-03 21:33:39,698: ERROR/MainProcess] consumer: Cannot connect to amqp://celery:**@rabbitmq:5672/my_vhost: [Errno 111] Connection refused.
Trying again in 6.00 seconds...

[2019-11-03 21:33:45,752: ERROR/MainProcess] consumer: Cannot connect to amqp://celery:**@rabbitmq:5672/my_vhost: [Errno 111] Connection refused.
Trying again in 8.00 seconds...

[2019-11-03 21:33:53,807: ERROR/MainProcess] consumer: Cannot connect to amqp://celery:**@rabbitmq:5672/my_vhost: [Errno 111] Connection refused.
Trying again in 10.00 seconds...

[2019-11-03 21:34:05,081: WARNING/MainProcess] /usr/local/lib/python3.7/site-packages/celery/fixups/django.py:202: UserWarning: Using settings.DEBUG leads to a memory leak, never use this setting in production environments!
  warnings.warn('Using settings.DEBUG leads to a memory leak, never '
